output/12:00.txt
VWAP at time: 12:00
Symbol  VWAP
--------------
PSR   83.8300
STNLU   10.1600
KBA   26.6100
GSIE   27.0800
NHA   9.6400
MYC   13.3000
AFTY   14.5200
IHC   36.1700
VBF   17.6100
WBIG   23.3400
MMD   19.7100
USWSW   0.6700
PGP   13.5995
ZB-G   26.8400
BFS-D   22.4200
YMLI   12.3300
EMP   23.7674
JHMU   28.7900
FDTS   36.1800
SDR   1.0000
QEMM   58.1900
BSCR   19.1500
JJS   41.7900
DAUD   28.4500
JHMT   42.7300
TSQ   6.1101
NRP   38.2000
UYM   54.5200
LDP   23.2045
PBJ   31.1630
SBB   33.9200
TCI   30.6600
WYY   0.4399
AHT-F   21.1533
VEGI   28.1500
MVC   8.8100
ULST   40.2950
NYF   54.9400
PLYM   15.5674
HUSV   23.3700
WIA   10.9100
UMDD   90.8333
AMH-G   22.4500
EGIF   14.0400
HYMB   55.7400
EMIF   29.6500
WEAT   6.0100
NAII   11.0400
ANH-C   24.6900
POPE   70.1200
KKR-A   26.8400
ECCA   25.4900
AMS   2.5161
FCOR   48.3900
QTS-A   25.4800
ADRD   20.5900
STT-D   26.4800
GLOP-A   23.5500
GAL   36.4350
WHLRP   10.2462
FLTR   25.0150
SSW-I   23.2600
BSJM   24.0500
BMLP   46.6600
RZG   113.3250
OMFL   26.4462
PMM   7.1150
DNI   10.8435
MNR-C   23.3660
IBDT   25.3500
STI-A   22.0059
GQRE   61.3536
FXB   126.6948
PTVCA   17.9000
DLR-J   22.9200
MSD   8.8300
DALI   18.5500
FONE   45.6200
BML-L   21.2600
FLC   18.3153
IYY   133.0000
CODI-A   19.4838
BAC-A   25.7708
EMX   1.1400
EWX   43.2500
AMRB   13.7611
FCAL   49.9700
ELU   22.9878
HAO   23.9300
EOD   5.1240
BSCJ   21.0800
GDXS   13.2000
FRC-D   24.1156
ROSEW   0.4200
USVM   49.6000
FLMNW   0.7995
PNF   12.5850
AKP   13.7620
WFE-A   25.7200
NES   13.2600
IPB   25.7500
SPE   12.7629
TCO-J   24.7658
ADRA   30.2500
SMLV   89.3868
GXG   8.8538
CRHM   3.1900
ACU   17.1100
CIM-A   25.2490
GLDM   13.1000
RETO   1.8800
PSB-U   23.8636
GIG+   0.2200
LSBK   15.3957
PSB-V   24.7309
SPFF   11.5000
RCD   98.1100
TVC   25.3100
DCP-B   23.9200
GS-B   26.3488
GDV-G   24.6233
PIY   10.3600
BSJL   24.3222
WIW   10.5131
STND   31.2000
USEQ   26.1400
CIZN   21.5483
TANNI   25.2728
JHX   10.8900
IRET-C   23.7400
THST   2.1400
CSPI   10.0000
LDUR   98.9800
BLES   26.6000
PCEF   21.4925
PNC-Q   24.8800
LTL   34.8900
TAWK   24.2400
RWGV   50.7700
RWLS   51.1800
PFIN   7.8200
CEY   24.5417
MMTM   114.8214
PWS   24.0000
AVH   4.6200
RF-B   26.4600
FRAK   12.5000
IMTB   48.4900
PCG-C   16.6400
NC   33.9655
LTPZ   62.5700
EHT   9.4800
FTAG   23.7054
GTO   50.6850
SSW-H   23.2500
MET-A   23.0200
MAGA   25.5000
PIHPP   22.1000
NNVC   0.3100
SIJ   16.4000
IQDY   23.6200
DOD   23.8000
SSG   17.5480
SHYD   24.3500
DEF   46.8600
PZN   8.3642
GGZ   11.1400
PPX   25.1700
DSS   0.9805
IAF   5.1792
USHY   47.6400
CMSC   25.5052
ZF   9.1929
GHII   25.6000
NEWTI   25.5921
TVE   24.9600
DNN   0.5179
HEWP   20.9500
NOM   12.3153
GS-D   19.0674
GIG^   0.2400
MHH   7.9900
DLNG-A   20.8500
SNV-D   25.1100
ABR-C   25.6400
ONEO   67.8200
NUAG   23.3700
TRT   2.9500
CLTL   105.4600
JPME   62.0600
WFHY   49.4000
EWO   19.9200
PDT   15.5854
CNP-B   52.7850
MITT-B   25.3313
VJET   2.0800
NTIC   30.9214
PCQ   16.9333
INF   11.6190
TCBIL   25.3000
ALD   44.0657
SHAG   49.1200
DTF   12.9520
GLADD   25.1012
AFGH   26.1000
SRC-A   22.2200
PPT   4.9769
EYESW   0.3300
NORW   12.2600
SDD   14.7600
CCM   3.1301
SGZA   24.9600
SRG-A   23.1833
INTF   25.7696
GVAL   22.8211
ELJ   25.3300
DCF   8.3580
TNP-E   21.6534
NOVN   1.3503
BYM   12.9863
DBGR   24.7100
PT   11.0000
ISCF   27.8400
DSWL   3.0300
ALYA   2.8419
THM   0.6199
JHMD   27.2306
GBR   1.7026
MFA-B   24.7700
GDO   15.9800
ALL-A   25.4967
PULS   50.0750
TDW+A   2.2200
UST   55.4400
OGIG   21.2567
TLTE   51.9614
PMT-B   24.7000
PYN   9.6100
HHS   3.0686
DBE   14.0000
AHT-D   24.9200
MSUS   22.8700
SRLN   45.8700
VIDI   24.5000
HCXZ   24.2425
GMO   0.2288
PLND   17.1400
BOUT   18.8781
FMN   13.0600
FLAG   39.4000
CII   15.1311
TZACU   10.1100
UBP   17.1093
ZMLP   13.5800
SOR   34.7302
DCP-C   23.7250
BWG   11.0400
YYY   17.2450
TCBIP   25.2000
BAC-C   26.3413
ISF   25.6723
ALL-B   25.1500
VER-F   25.1852
BHR-B   18.0050
MH-A   6.4024
UNMA   25.0020
HTD   22.7264
TKKSR   0.2600
TKKSW   0.1613
EVM   10.2700
BSD   12.6200
TGP-A   24.8995
JHB   9.6843
FTSD   94.5300
ALO   0.8075
JPGB   48.5000
TYNS   28.2300
PTNQ   32.7300
ASFI   4.2550
FDRR   30.2473
PEO   16.1172
BOSS   18.1300
PBI-B   24.2400
LVHB   31.1800
SMMV   30.8689
FRN   12.8300
DDG   24.8500
PUTW   26.0000
EUSA   54.2530
GAMR   41.9394
QEFA   59.5400
RHS   120.8084
SPVM   26.6200
CLRG   23.3587
MIY   12.8098
MHNC   17.7568
CUBI-E   25.8300
HDGE   7.5900
NAZ   12.1407
SLTB   25.3427
GNL-A   24.5300
KLDW   31.1000
UWN   2.4700
UQM   1.6499
MFINL   25.6000
FXS   102.8700
PSB-W   22.0000
EQRR   41.8000
VCF   13.8000
BKK   14.9300
CLNY-G   21.7500
PAK   8.9918
BFRA   13.3300
CDR-B   24.4778
HE-U   26.4000
BXP-B   24.7842
ESGV   45.9452
TRTY   24.0168
DBEZ   28.2400
JPM-H   25.9850
STAG-C   25.6400
JPM-E   25.6363
USB-P   25.1234
DUKB   24.9200
FXO   29.7375
TIPZ   56.1887
TLH   132.8922
IDEV   51.9949
HTY   6.8758
TAT   1.2700
SAMA   9.6700
NEWTZ   25.6600
BPOPN   25.7100
HEWU   22.1800
CLIX   47.1600
ALGRU   10.3800
NNY   9.4482
ADILW   0.7494
LN   36.3418
NMI   10.5494
JHAA   10.2543
ENTX   4.0542
HAFC   22.3401
TWLVW   0.2290
ITM   47.6311
AC   41.2919
MYI   12.2501
WFC-W   25.3500
GRFS   18.6139
BTT   21.6938
JMU   0.8051
FXD   39.9926
NS-B   20.3000
ISMD   25.4349
DES   26.9312
INFU   3.7323
UAA   20.9353
CBL-E   12.9863
CWB   49.6338
EVI   34.8557
HPI   20.8505
HBANN   25.4100
PDN   29.3231
ATKR   22.1180
ARYAU   10.4800
GYB   20.8625
UDN   21.0300
USRT   49.7498
FTXG   18.8734
GBAB   22.4369
RWL   49.7900
SMTS   1.8250
MUH   13.6500
BKJ   13.4633
EDEN   59.0500
OCUL   3.7552
ZOM   0.9078
USAC   15.0526
GMFL   25.8300
DOL   44.8900
DOO   39.9000
MTDR   19.2750
INS   21.0471
AXS-D   23.4267
ESGRP   25.1622
AFSI-A   8.0900
CHRA   7.3008
QVAL   28.3400
EIV   11.7009
IHG   58.5290
WFC-T   25.7900
ICLN   9.2795
CVCY   19.7556
BANFP   26.4488
OUSA   31.1077
EWK   17.4800
ONCE   43.5359
PHI   24.9354
PFXF   18.7913
AVGR   0.3237
ROUS   29.8900
GLPI   36.7800
OSN   1.8500
ATMP   19.9806
CATC   75.6429
GLOP-C   22.6788
BAC-K   25.4500
PLYA   7.8607
BHK   12.9073
MUFG   5.3185
EQC-D   25.7247
IEIH   24.7300
BSGM   4.3019
IPG   22.6572
NEE-I   23.7733
IYC   193.2276
NGHCP   21.2776
BCRH   6.4385
PS   28.3288
DTW   23.8748
JLS   22.6175
LLL   196.6490
BRG-A   25.3400
WFC-P   23.4400
FTACW   0.7999
EXFO   3.2867
EGY   1.8564
WES   49.7364
STZ.B   169.4800
AVCO   5.5172
IRBO   22.3865
LPG   5.4510
ETON   6.1999
BWX   27.8233
HSBC-A   25.7850
CMU   4.5381
RILYI   24.9400
VKQ   11.7775
PFD   12.9208
PEI-D   18.0425
GLV   10.7070
MPVD   1.1700
ANIP   53.6047
PGF   18.0512
WPP   57.7807
MFDX   23.7300
SBI   8.5951
XPP   65.3640
HYXU   49.0600
MFT   13.0822
EDN   28.4191
NS-C   23.4600
CLNY-I   20.3400
ISG   25.5577
MSFT   104.9702
ALLY-A   26.1450
PEBK   25.7191
AUSE   51.3500
DDD   12.0672
BBT-G   24.0100
BBT-D   25.5767
SZNE   25.2300
NRCG+   0.9977
NTNX   49.9175
BAC-E   21.3483
PSB-Y   21.8596
UGP   15.0987
UZA   24.4929
TMCXW   0.4100
NETS   2.3840
FCT   11.7668
PHIOW   0.0250
JASNW   0.0080
WHLRW   0.0100
LFACW   0.3500
ESXB   7.3910
BRACW   0.2400
AMBCW   9.2500
TDW+   0.5800
OXBRW   0.0121
EFC   16.3390
PGHY   23.0713
BFZ   12.3840
CCBG   23.5467
RJI   5.2340
LXFR   19.8709
COMG   21.2000
ALFA   45.2950
DHDG   21.9600
BSJP   23.4800
SMIN   35.7474
BRACR   0.3225
PML   13.4599
USDP   11.2600
SMDD   10.0962
WCG   275.2631
JPUS   69.4803
HA   29.9739
IMTE   6.3838
USOD   7.1118
VNLA   49.3409
TFI   48.2775
BSCP   19.9883
JPGE   57.7400
SPXL   38.6426
EARN   11.5510
PJH   25.0250
ORG   26.2076
SF-A   25.4744
OHAI   1.1600
NTX   12.7511
C-L*   25.4100
BBF   12.7800
SAL   38.6182
MVF   8.7350
PSA-E   22.1700
MQT   11.8389
JCAP-B   23.5000
APO-A   24.5577
HYB   8.1643
MER-K   25.7867
HSON   1.4379
CAAP   6.9962
SGG   43.4500
LEO   7.6325
ITEQ   34.1450
SFIX   23.2304
GOAT   25.9481
FAN   12.5633
THQ   17.4492
SRT   6.8454
TSRI   5.5800
TAC   5.3408
PFFL   23.6547
JPN   26.1301
NUE   59.8344
MNI   6.0724
SLVP   8.7646
DMAC   3.7541
MHE   11.8900
ETP-D   24.6167
DTLA-   21.0000
