output/13:00.txt
VWAP at time: 13:00
Symbol  VWAP
--------------
CIO-A   22.0000
LRGE   30.6900
JHY   10.0000
IZRL   20.7800
PSB-X   22.4300
IGEB   48.1600
TDTF   24.1800
CHGX   18.9800
DDLS   29.1100
ACES   25.0600
IHY   23.9700
USMF   27.7700
FILL   19.7712
MCN   6.6783
CNYA   24.5500
VMM   12.1683
RHE-A   3.7500
FIHD   153.8500
GMF   92.4550
EMDV   56.4700
HYGV   47.4500
TUZ   50.1800
IPAC   53.8276
CZA   63.9600
LOAC   9.9500
MFO   25.5800
CNACR   0.1410
FDNI   20.2850
VIOG   149.0800
IQDG   26.9800
FLIN   21.1600
WIL   64.4500
AUSF   23.8000
DGZ   14.0200
WILC   8.1400
DFP   22.4700
AAAU   13.1000
AEF   7.0138
IVR-A   24.9780
CEL   5.0700
FEO   13.3600
DJPY   23.0300
UMH-B   26.0400
EELV   24.0900
TCTL   29.0300
MFCB   6.7600
MIND   3.9500
MCX   24.8800
AUG   1.0292
PY   30.3000
JPXN   57.8100
LGI   14.5200
FVAL   32.0290
NYMTP   23.0401
GS-A   19.1100
SVT   11.4600
MVCD   25.2550
BML-H   19.3520
MUJ   12.9500
SUSC   24.3000
NXN   13.0950
RIVE   12.6000
DL   7.1100
NUBD   24.3700
LGLV   93.4100
RFDA   30.3353
PXMV   30.1443
DVP   31.8300
PBTP   24.5000
CODI-B   20.2900
SSWN   25.1500
XYF   5.3600
GDV-A   25.7200
GLOG-A   25.8300
YLDE   27.4900
DVOL   19.0536
FGB   6.1000
DD-B   99.9840
NEE-K   24.3900
BKTI   4.0700
KIM-M   21.9800
CBND   31.1894
HCCHR   0.2900
DTEC   26.5750
TMK-C   26.2900
MDLQ   22.3885
SPRT   2.5000
PYS   15.6000
ENJ   24.0200
VNRX   2.5457
PSR   83.8300
STNLU   10.1600
KBA   26.6100
GSIE   27.1223
NHA   9.6485
MYC   13.2374
AFTY   14.5200
TPGH+   1.2500
IHC   36.1700
VBF   17.6084
WBIG   23.3400
MMD   19.6302
USWSW   0.6700
PGP   13.6084
ZB-G   26.8400
BFS-D   22.4200
YMLI   12.3300
EMP   23.7998
JHMU   28.7755
FDTS   36.1800
JHS   13.4200
SDR   1.0000
QEMM   58.1900
BSCR   19.1450
JJS   41.7900
DAUD   28.4500
JHMT   42.7300
TSQ   6.1115
NRP   38.2000
UYM   54.5200
FDM   44.5700
LDP   23.2263
PBJ   31.1329
SBB   33.9200
TCI   30.6600
WYY   0.4399
BSJN   25.5495
AHT-F   21.1533
VEGI   28.2089
MVC   8.8000
ULST   40.2950
NYF   54.9350
PLYM   15.5739
HUSV   23.3700
WIA   10.9231
UMDD   90.8333
AMH-G   22.4507
EGIF   14.0400
HYMB   55.7450
EMIF   29.6500
WEAT   6.0100
NAII   11.0686
ANH-C   24.6900
POPE   69.9960
KKR-A   26.8400
ECCA   25.4900
AMS   2.5161
FCOR   48.3900
QTS-A   25.4800
ADRD   20.5900
STT-D   26.4800
GLOP-A   23.1321
GAL   36.4350
WHLRP   10.2766
FLTR   25.0150
SSW-I   23.2600
BSJM   24.0550
BMLP   46.8337
RZG   113.3250
OMFL   26.4462
PMM   7.1100
DNI   10.8583
MNR-C   23.3367
IBDT   25.3500
STI-A   22.0059
GQRE   61.3536
FXB   126.6886
PTVCA   17.9000
DLR-J   22.9200
MSD   8.8350
DALI   18.5500
FONE   45.6200
BML-L   21.2843
FLC   18.3175
IYY   133.0000
CODI-A   19.4838
FOF   12.0600
BAC-A   25.7961
EMX   1.1400
EWX   43.2501
AMRB   13.7611
FCAL   49.9700
ELU   22.9881
HAO   23.9296
EOD   5.1240
BSCJ   21.0800
GDXS   13.2920
FRC-D   24.1344
ROSEW   0.4200
USVM   49.6000
FLMNW   0.7995
PNF   12.5850
AKP   13.7620
WFE-A   25.7167
NES   13.2600
IPB   25.7500
SPE   12.7629
TCO-J   24.7658
ADRA   30.2500
SMLV   89.3868
GXG   8.8538
CRHM   3.1900
ACU   17.1100
CIM-A   25.2548
GLDM   13.0919
RETO   1.7933
PSB-U   23.8290
GIG+   0.2160
LSBK   15.3957
PSB-V   24.7305
SPFF   11.5180
RCD   98.1100
TVC   25.3137
DCP-B   23.9200
GS-B   26.3492
GDV-G   24.6233
PIY   10.3600
BSJL   24.3259
WIW   10.4883
STND   31.2000
USEQ   26.1400
CIZN   21.5652
TANNI   25.3442
JHX   10.8768
IRET-C   23.7400
THST   2.1400
CSPI   9.8074
LDUR   98.9800
BLES   26.6000
PCEF   21.5035
PNC-Q   24.8631
LTL   34.8900
TAWK   24.2400
RWGV   50.7700
RWLS   51.1800
PFIN   7.8405
CEY   24.5417
MMTM   114.8214
PWS   24.0000
AVH   4.6200
RF-B   26.4600
FRAK   12.5000
IMTB   48.4900
PCG-C   16.6400
NC   33.9655
LTPZ   62.5400
EHT   9.5000
FTAG   23.7054
GTO   50.6833
SSW-H   23.2500
MET-A   23.0452
MAGA   25.5000
PIHPP   22.0157
NNVC   0.3100
SIJ   16.4000
IQDY   23.6200
DOD   23.8536
SSG   17.5480
SHYD   24.3467
DEF   46.8600
PZN   8.3695
GGZ   11.1400
PPX   25.1700
DSS   0.9804
IAF   5.1836
USHY   47.6488
CMSC   25.5052
ZF   9.1929
GHII   25.6000
NEWTI   25.5921
TVE   24.9600
DNN   0.5179
HEWP   20.9500
NOM   12.3313
GS-D   19.0673
GIG^   0.2400
MHH   7.9900
DLNG-A   20.8500
SNV-D   25.1100
ABR-C   25.6400
ONEO   67.8200
NUAG   23.3700
TRT   2.9500
CLTL   105.4600
JPME   62.0600
WFHY   49.4000
EWO   19.9200
PDT   15.5854
CNP-B   52.7560
MITT-B   25.3313
VJET   2.0800
NTIC   30.9214
PCQ   16.9414
INF   11.6190
TCBIL   25.3000
ALD   44.0657
SHAG   49.1200
DTF   12.9520
GLADD   25.1012
AFGH   26.1000
SRC-A   22.2200
PPT   4.9631
EYESW   0.3300
NORW   12.2600
SDD   14.7600
CCM   3.1301
SGZA   24.9600
SRG-A   23.2339
DEMG   24.7850
INTF   25.7696
GVAL   22.8211
ELJ   25.3300
DCF   8.3600
TNP-E   21.5245
NOVN   1.3503
BYM   12.9843
DBGR   24.7100
PT   11.0000
WHLRD   11.8384
ISCF   27.8478
CIM-C   24.8400
DSWL   3.0300
ALYA   2.8419
THM   0.6199
JHMD   27.2306
GBR   1.7656
MFA-B   24.7700
GDO   15.9498
ALL-A   25.4967
PULS   50.0750
TDW+A   2.2200
UST   55.4400
OGIG   21.2567
TLTE   51.9700
PMT-B   24.7000
PYN   9.6033
HHS   3.1207
DBE   14.0000
AHT-D   24.9200
MSUS   22.8700
SRLN   45.8563
VIDI   24.5332
DJD   34.5400
HCXZ   24.2425
GMO   0.2291
PLND   17.1400
BOUT   18.8781
FMN   13.0486
FLAG   39.4000
CII   15.1311
TZACU   10.1100
UBP   17.1248
ZMLP   13.5800
SOR   34.7302
DCP-C   23.7250
BWG   11.0400
YYY   17.2486
TCBIP   25.2052
BAC-C   26.3290
ISF   25.6787
ALL-B   25.1500
VER-F   25.1852
BHR-B   18.0050
MH-A   6.3959
UNMA   25.0020
HTD   22.7638
TKKSR   0.2600
TKKSW   0.1613
EVM   10.2700
BSD   12.6191
TGP-A   24.8995
JHB   9.6892
FTSD   94.5300
ALO   0.8075
JPGB   48.5050
TYNS   28.2300
PTNQ   32.7300
ASFI   4.2550
FDRR   30.2491
PEO   16.1172
BOSS   18.1300
PBI-B   24.2400
LVHB   31.1471
SMMV   30.8689
FRN   12.8300
DDG   24.8500
PUTW   26.0000
EUSA   54.2530
GAMR   41.9397
QEFA   59.5400
RHS   120.8036
SPVM   26.6200
CLRG   23.3587
MIY   12.8065
MHNC   17.7568
CUBI-E   25.8300
HDGE   7.5900
NAZ   12.1413
SLTB   25.3425
GNL-A   24.5300
KLDW   31.1000
UWN   2.4700
UQM   1.6499
MFINL   25.6000
FXS   102.8700
PSB-W   22.0000
EQRR   41.8000
VCF   13.8000
BKK   14.9300
CLNY-G   21.7500
PAK   8.9918
BFRA   13.3300
CDR-B   24.4778
HE-U   26.4000
BXP-B   24.7857
ESGV   45.9452
TRTY   24.0168
DBEZ   28.2400
JPM-H   25.9703
STAG-C   25.6400
JPM-E   25.6363
USB-P   25.1207
DUKB   24.9350
FXO   29.7367
TIPZ   56.1887
TLH   132.8922
IDEV   51.9949
HTY   6.8777
TAT   1.2700
SAMA   9.6700
NEWTZ   25.6433
BPOPN   25.7100
HEWU   22.1800
CLIX   47.1600
ALGRU   10.3800
NNY   9.4482
ADILW   0.7494
LN   36.5257
NMI   10.5494
JHAA   10.2543
ENTX   4.0542
HAFC   22.3486
TWLVW   0.2290
ITM   47.6311
AC   41.2916
MYI   12.2483
WFC-W   25.3500
GRFS   18.6235
BTT   21.6938
JMU   0.8051
FXD   39.9926
NS-B   20.3000
ISMD   25.4349
DES   26.9245
INFU   3.7323
UAA   20.9299
CBL-E   12.9863
CWB   49.6391
EVI   34.8557
HPI   20.8676
HBANN   25.3660
PDN   29.3277
ATKR   22.1154
ARYAU   10.4800
GYB   20.8625
UDN   21.0300
USRT   49.7498
FTXG   18.8734
GBAB   22.4369
RWL   49.7900
SMTS   1.8260
MUH   13.6500
BKJ   13.3948
EDEN   59.0500
OCUL   3.7534
ZOM   0.8866
USAC   15.0600
GMFL   25.8300
DOL   44.8900
DOO   39.8967
MTDR   19.3606
INS   21.0734
AXS-D   23.4082
ESGRP   25.1622
AFSI-A   8.0904
CHRA   7.2944
QVAL   28.3400
EIV   11.6931
IHG   58.5204
WFC-T   25.7900
ICLN   9.2789
CVCY   19.7526
BANFP   26.4488
OUSA   31.0829
EWK   17.4800
ONCE   43.5983
PHI   24.9176
PFXF   18.7913
AVGR   0.3235
ROUS   29.8900
GLPI   36.7764
OSN   1.8500
ATMP   19.9886
CATC   75.7937
GLOP-C   22.6788
BAC-K   25.4621
PLYA   7.8547
BHK   12.9101
MUFG   5.3283
EQC-D   25.7183
DLBS   18.3300
IEIH   24.7300
BSGM   4.3019
IPG   22.6595
NEE-I   23.7716
IYC   193.0478
NGHCP   21.2663
BCRH   6.4460
PS   28.3150
DTW   23.8897
JLS   22.6175
LLL   196.8696
BRG-A   25.3400
WFC-P   23.5540
FTACW   0.7990
EXFO   3.2867
EGY   1.8560
WES   49.8004
STZ.B   169.4800
AVCO   5.5167
IRBO   22.3865
LPG   5.4430
ETON   6.1999
BWX   27.8235
HSBC-A   25.7850
CMU   4.5377
RILYI   24.9475
VKQ   11.7670
PFD   12.9043
PEI-D   18.0425
GLV   10.7091
